Workbook

Sheet DAXX MIDIA PE
B1: DAXX MIDIA PE - cód. 1220 | D1: 46023 | E1: =D1+1 -> 46024 | F1: =E1+1 -> 46025 | G1: =F1+1 -> 46026 | H1: =G1+1 -> 46027 | I1: =H1+1 -> 46028 | J1: =I1+1 -> 46029 | K1: =J1+1 -> 46030 | L1: =K1+1 -> 46031 | ... AH1: =AG1+1 -> 46053 | AI1: TOTAL JAN | AK1: =EOMONTH(AE1,0)+1 -> 46054 | AL1: =AK1+1 -> 46055 | AM1: =AL1+1 -> 46056 | AN1: =AM1+1 -> 46057 | AO1: =AN1+1 -> 46058 | AP1: =AO1+1 -> 46059 | AQ1: =AP1+1 -> 46060 | AR1: =AQ1+1 -> 46061 | AS1: =AR1+1 -> 46062 | ... BL1: =BK1+1 -> 46081 | BN1: TOTAL FEV | BP1: =EOMONTH(BJ1,0)+1 -> 46082 | BQ1: =BP1+1 -> 46083 | BR1: =BQ1+1 -> 46084 | BS1: =BR1+1 -> 46085 | BT1: =BS1+1 -> 46086 | BU1: =BT1+1 -> 46087 | BV1: =BU1+1 -> 46088 | BW1: =BV1+1 -> 46089 | BX1: =BW1+1 -> 46090 | ... CT1: =CS1+1 -> 46112 | CU1: TOTAL MAR | CW1: =EOMONTH(CQ1,0)+1 -> 46113 | CX1: =CW1+1 -> 46114 | CY1: =CX1+1 -> 46115 | CZ1: =CY1+1 -> 46116 | DA1: =CZ1+1 -> 46117 | DB1: =DA1+1 -> 46118 | DC1: =DB1+1 -> 46119 | DD1: =DC1+1 -> 46120 | DE1: =DD1+1 -> 46121 | ... DZ1: =DY1+1 -> 46142 | EA1: TOTAL ABR | EC1: =EOMONTH(DW1,0)+1 -> 46143 | ED1: =EC1+1 -> 46144 | EE1: =ED1+1 -> 46145 | EF1: =EE1+1 -> 46146 | EG1: =EF1+1 -> 46147 | EH1: =EG1+1 -> 46148 | EI1: =EH1+1 -> 46149 | EJ1: =EI1+1 -> 46150 | EK1: =EJ1+1 -> 46151 | ... FG1: =FF1+1 -> 46173 | FH1: TOTAL MAI | FJ1: =EOMONTH(FD1,0)+1 -> 46174 | FK1: =FJ1+1 -> 46175 | FL1: =FK1+1 -> 46176 | FM1: =FL1+1 -> 46177 | FN1: =FM1+1 -> 46178 | FO1: =FN1+1 -> 46179 | FP1: =FO1+1 -> 46180 | FQ1: =FP1+1 -> 46181 | FR1: =FQ1+1 -> 46182 | ... GM1: =GL1+1 -> 46203 | GN1: TOTAL JUN | GP1: =EOMONTH(GJ1,0)+1 -> 46204 | GQ1: =GP1+1 -> 46205 | GR1: =GQ1+1 -> 46206 | GS1: =GR1+1 -> 46207 | GT1: =GS1+1 -> 46208 | GU1: =GT1+1 -> 46209 | GV1: =GU1+1 -> 46210 | GW1: =GV1+1 -> 46211 | GX1: =GW1+1 -> 46212 | ... HT1: =HS1+1 -> 46234 | HU1: TOTAL JUL | HW1: =EOMONTH(HQ1,0)+1 -> 46235 | HX1: =HW1+1 -> 46236 | HY1: =HX1+1 -> 46237 | HZ1: =HY1+1 -> 46238 | IA1: =HZ1+1 -> 46239 | IB1: =IA1+1 -> 46240 | IC1: =IB1+1 -> 46241 | ID1: =IC1+1 -> 46242 | IE1: =ID1+1 -> 46243 | ... JA1: =IZ1+1 -> 46265 | JB1: TOTAL AGO | JD1: =EOMONTH(IX1,0)+1 -> 46266 | JE1: =JD1+1 -> 46267 | JF1: =JE1+1 -> 46268 | JG1: =JF1+1 -> 46269 | JH1: =JG1+1 -> 46270 | JI1: =JH1+1 -> 46271 | JJ1: =JI1+1 -> 46272 | JK1: =JJ1+1 -> 46273 | JL1: =JK1+1 -> 46274 | ... KG1: =KF1+1 -> 46295 | KH1: TOTAL SET | KJ1: =EOMONTH(KD1,0)+1 -> 46296 | KK1: =KJ1+1 -> 46297 | KL1: =KK1+1 -> 46298 | KM1: =KL1+1 -> 46299 | KN1: =KM1+1 -> 46300 | KO1: =KN1+1 -> 46301 | KP1: =KO1+1 -> 46302 | KQ1: =KP1+1 -> 46303 | KR1: =KQ1+1 -> 46304 | ... LN1: =LM1+1 -> 46326 | LO1: TOTAL OUT | LQ1: =EOMONTH(LK1,0)+1 -> 46327 | LR1: =LQ1+1 -> 46328 | LS1: =LR1+1 -> 46329 | LT1: =LS1+1 -> 46330 | LU1: =LT1+1 -> 46331 | LV1: =LU1+1 -> 46332 | LW1: =LV1+1 -> 46333 | LX1: =LW1+1 -> 46334 | LY1: =LX1+1 -> 46335 | ... MT1: =MS1+1 -> 46356 | MU1: TOTAL NOV | MW1: =EOMONTH(MQ1,0)+1 -> 46357 | MX1: =MW1+1 -> 46358 | MY1: =MX1+1 -> 46359 | MZ1: =MY1+1 -> 46360 | NA1: =MZ1+1 -> 46361 | NB1: =NA1+1 -> 46362 | NC1: =NB1+1 -> 46363 | ND1: =NC1+1 -> 46364 | NE1: =ND1+1 -> 46365 | ... OA1: =NZ1+1 -> 46387 | OB1: TOTAL DEZ | OC1: ACUMULADO | OE1: =EOMONTH(NX1,0)+1 -> 46388 | OF1: =OE1+1 -> 46389 | OG1: =OF1+1 -> 46390 | OH1: =OG1+1 -> 46391 | OI1: =OH1+1 -> 46392 | OJ1: =OI1+1 -> 46393 | OK1: =OJ1+1 -> 46394 | OL1: =OK1+1 -> 46395 | OM1: =OL1+1 -> 46396 | ... PI1: =PH1+1 -> 46418 | PJ1: TOTAL JAN PA | PL1: =EOMONTH(PF1,0)+1 -> 46419 | PM1: =PL1+1 -> 46420 | PN1: =PM1+1 -> 46421 | PO1: =PN1+1 -> 46422 | PP1: =PO1+1 -> 46423 | PQ1: =PP1+1 -> 46424 | PR1: =PQ1+1 -> 46425 | PS1: =PR1+1 -> 46426 | PT1: =PS1+1 -> 46427 | ... QM1: =QL1+1 -> 46446 | QO1: TOTAL FEV PA | QQ1: =EOMONTH(QK1,0)+1 -> 46447 | QR1: =QQ1+1 -> 46448 | QS1: =QR1+1 -> 46449 | QT1: =QS1+1 -> 46450 | QU1: =QT1+1 -> 46451 | QV1: =QU1+1 -> 46452 | QW1: =QV1+1 -> 46453 | QX1: =QW1+1 -> 46454 | QY1: =QX1+1 -> 46455 | ... RU1: =RT1+1 -> 46477 | RV1: TOTAL MAR PA | RW1: ACUMULADO PA
A3: 1 | B3: RECEITAS
B4: Outras Receitas | AI4: =SUM(D4:AH4) -> 0 | BN4: =SUM(AK4:BM4) -> 0 | CU4: =SUM(BP4:CT4) -> 0 | EA4: =SUM(CW4:DZ4) -> 0 | FH4: =SUM(EC4:FG4) -> 0 | GN4: =SUM(FJ4:GM4) -> 0 | HU4: =SUM(GP4:HT4) -> 0 | JB4: =SUM(HW4:JA4) -> 0 | KH4: =SUM(JD4:KG4) -> 0 | LO4: =SUM(KJ4:LN4) -> 0 | MU4: =SUM(LQ4:MT4) -> 0 | OB4: =SUM(MW4:OA4) -> 0 | OC4: =SUM(AI4,BN4,CU4,EA4,FH4,GN4,HU4,JB4,KH4,LO4,MU4,OB4) -> 0 | PJ4: =SUM(OE4:PI4) -> 0 | QO4: =SUM(PL4:QN4) -> 0 | RV4: =SUM(QQ4:RU4) -> 0 | RW4: =SUM(PJ4,QO4,RV4) -> 0
B5: Resgate Aplicação | AI5: =SUM(D5:AH5) -> 0 | BN5: =SUM(AK5:BM5) -> 0 | CU5: =SUM(BP5:CT5) -> 0 | EA5: =SUM(CW5:DZ5) -> 0 | FH5: =SUM(EC5:FG5) -> 0 | GN5: =SUM(FJ5:GM5) -> 0 | HU5: =SUM(GP5:HT5) -> 0 | JB5: =SUM(HW5:JA5) -> 0 | KH5: =SUM(JD5:KG5) -> 0 | LO5: =SUM(KJ5:LN5) -> 0 | MU5: =SUM(LQ5:MT5) -> 0 | OB5: =SUM(MW5:OA5) -> 0 | OC5: =SUM(AI5,BN5,CU5,EA5,FH5,GN5,HU5,JB5,KH5,LO5,MU5,OB5) -> 0 | PJ5: =SUM(OE5:PI5) -> 0 | QO5: =SUM(PL5:QN5) -> 0 | RV5: =SUM(QQ5:RU5) -> 0 | RW5: =SUM(PJ5,QO5,RV5) -> 0
B6: Empréstimos Sócios | AI6: =SUM(D6:AH6) -> 0 | BN6: =SUM(AK6:BM6) -> 0 | CU6: =SUM(BP6:CT6) -> 0 | EA6: =SUM(CW6:DZ6) -> 0 | FH6: =SUM(EC6:FG6) -> 0 | GN6: =SUM(FJ6:GM6) -> 0 | HU6: =SUM(GP6:HT6) -> 0 | JB6: =SUM(HW6:JA6) -> 0 | KH6: =SUM(JD6:KG6) -> 0 | LO6: =SUM(KJ6:LN6) -> 0 | MU6: =SUM(LQ6:MT6) -> 0 | OB6: =SUM(MW6:OA6) -> 0 | OC6: =SUM(AI6,BN6,CU6,EA6,FH6,GN6,HU6,JB6,KH6,LO6,MU6,OB6) -> 0 | PJ6: =SUM(OE6:PI6) -> 0 | QO6: =SUM(PL6:QN6) -> 0 | RV6: =SUM(QQ6:RU6) -> 0 | RW6: =SUM(PJ6,QO6,RV6) -> 0
B7: Mútuo Sócios | AI7: =SUM(D7:AH7) -> 0 | BN7: =SUM(AK7:BM7) -> 0 | CU7: =SUM(BP7:CT7) -> 0 | EA7: =SUM(CW7:DZ7) -> 0 | FH7: =SUM(EC7:FG7) -> 0 | GN7: =SUM(FJ7:GM7) -> 0 | HU7: =SUM(GP7:HT7) -> 0 | JB7: =SUM(HW7:JA7) -> 0 | KH7: =SUM(JD7:KG7) -> 0 | LO7: =SUM(KJ7:LN7) -> 0 | MU7: =SUM(LQ7:MT7) -> 0 | OB7: =SUM(MW7:OA7) -> 0 | OC7: =SUM(AI7,BN7,CU7,EA7,FH7,GN7,HU7,JB7,KH7,LO7,MU7,OB7) -> 0 | PJ7: =SUM(OE7:PI7) -> 0 | QO7: =SUM(PL7:QN7) -> 0 | RV7: =SUM(QQ7:RU7) -> 0 | RW7: =SUM(PJ7,QO7,RV7) -> 0
B8: Mútuo CNPJ - outras empresas Grupo | AI8: =SUM(D8:AH8) -> 0 | AO8: =20000 -> 20000 | BN8: =SUM(AK8:BM8) -> 20000 | CU8: =SUM(BP8:CT8) -> 0 | EA8: =SUM(CW8:DZ8) -> 0 | FH8: =SUM(EC8:FG8) -> 0 | GN8: =SUM(FJ8:GM8) -> 0 | HU8: =SUM(GP8:HT8) -> 0 | JB8: =SUM(HW8:JA8) -> 0 | KH8: =SUM(JD8:KG8) -> 0 | LO8: =SUM(KJ8:LN8) -> 0 | MU8: =SUM(LQ8:MT8) -> 0 | OB8: =SUM(MW8:OA8) -> 0 | OC8: =SUM(AI8,BN8,CU8,EA8,FH8,GN8,HU8,JB8,KH8,LO8,MU8,OB8) -> 20000 | PJ8: =SUM(OE8:PI8) -> 0 | QO8: =SUM(PL8:QN8) -> 0 | RV8: =SUM(QQ8:RU8) -> 0 | RW8: =SUM(PJ8,QO8,RV8) -> 0
B9: Empréstimos Bancário | AI9: =SUM(D9:AH9) -> 0 | BN9: =SUM(AK9:BM9) -> 0 | CU9: =SUM(BP9:CT9) -> 0 | EA9: =SUM(CW9:DZ9) -> 0 | FH9: =SUM(EC9:FG9) -> 0 | GN9: =SUM(FJ9:GM9) -> 0 | HU9: =SUM(GP9:HT9) -> 0 | JB9: =SUM(HW9:JA9) -> 0 | KH9: =SUM(JD9:KG9) -> 0 | LO9: =SUM(KJ9:LN9) -> 0 | MU9: =SUM(LQ9:MT9) -> 0 | OB9: =SUM(MW9:OA9) -> 0 | OC9: =SUM(AI9,BN9,CU9,EA9,FH9,GN9,HU9,JB9,KH9,LO9,MU9,OB9) -> 0 | PJ9: =SUM(OE9:PI9) -> 0 | QO9: =SUM(PL9:QN9) -> 0 | RV9: =SUM(QQ9:RU9) -> 0 | RW9: =SUM(PJ9,QO9,RV9) -> 0
B10: Rendimento Banco C/c | H10: 1.76 | Q10: 2.76 | W10: 0.04 | AC10: 0.61 | AG10: 3.52 | AI10: =SUM(D10:AH10) -> 8.69 | AT10: 2.99 | BI10: 0.03 | BK10: 0.03 | BN10: =SUM(AK10:BM10) -> 3.05 | BT10: 0.13 | CN10: 0.07 | CT10: 0.09 | CU10: =SUM(BP10:CT10) -> 0.29 | DB10: 0.27 | DZ10: 0.14 | EA10: =SUM(CW10:DZ10) -> 0.41 | EG10: 0.4 | EN10: 0.31 | EV10: 0.02 | FE10: 0.46 | FH10: =SUM(EC10:FG10) -> 1.19 | GN10: =SUM(FJ10:GM10) -> 0 | HU10: =SUM(GP10:HT10) -> 0 | JB10: =SUM(HW10:JA10) -> 0 | KH10: =SUM(JD10:KG10) -> 0 | LO10: =SUM(KJ10:LN10) -> 0 | MU10: =SUM(LQ10:MT10) -> 0 | OB10: =SUM(MW10:OA10) -> 0 | OC10: =SUM(AI10,BN10,CU10,EA10,FH10,GN10,HU10,JB10,KH10,LO10,MU10,OB10) -> 13.63 | PJ10: =SUM(OE10:PI10) -> 0 | QO10: =SUM(PL10:QN10) -> 0 | RV10: =SUM(QQ10:RU10) -> 0 | RW10: =SUM(PJ10,QO10,RV10) -> 0
B11: Receita Operacional - REFATURAMENTO VEÍCULO | AI11: =SUM(D11:AH11) -> 0 | BN11: =SUM(AK11:BM11) -> 0 | CU11: =SUM(BP11:CT11) -> 0 | EA11: =SUM(CW11:DZ11) -> 0 | FH11: =SUM(EC11:FG11) -> 0 | GN11: =SUM(FJ11:GM11) -> 0 | HU11: =SUM(GP11:HT11) -> 0 | JB11: =SUM(HW11:JA11) -> 0 | KH11: =SUM(JD11:KG11) -> 0 | LO11: =SUM(KJ11:LN11) -> 0 | MU11: =SUM(LQ11:MT11) -> 0 | OB11: =SUM(MW11:OA11) -> 0 | OC11: =SUM(AI11,BN11,CU11,EA11,FH11,GN11,HU11,JB11,KH11,LO11,MU11,OB11) -> 0 | PJ11: =SUM(OE11:PI11) -> 0 | QO11: =SUM(PL11:QN11) -> 0 | RV11: =SUM(QQ11:RU11) -> 0 | RW11: =SUM(PJ11,QO11,RV11) -> 0
B12: Receita Operacional - REFATURAMENTO VEÍCULO (CUSTO COMISSÃO DO REPASSE) | AI12: =SUM(D12:AH12) -> 0 | BN12: =SUM(AK12:BM12) -> 0 | CU12: =SUM(BP12:CT12) -> 0 | EA12: =SUM(CW12:DZ12) -> 0 | FH12: =SUM(EC12:FG12) -> 0 | GN12: =SUM(FJ12:GM12) -> 0 | HU12: =SUM(GP12:HT12) -> 0 | JB12: =SUM(HW12:JA12) -> 0 | KH12: =SUM(JD12:KG12) -> 0 | LO12: =SUM(KJ12:LN12) -> 0 | MU12: =SUM(LQ12:MT12) -> 0 | OB12: =SUM(MW12:OA12) -> 0 | OC12: =SUM(AI12,BN12,CU12,EA12,FH12,GN12,HU12,JB12,KH12,LO12,MU12,OB12) -> 0 | PJ12: =SUM(OE12:PI12) -> 0 | QO12: =SUM(PL12:QN12) -> 0 | RV12: =SUM(QQ12:RU12) -> 0 | RW12: =SUM(PJ12,QO12,RV12) -> 0
B13: Receita Operacional - VENDAS (CLIENTE) | AI13: =SUM(D13:AH13) -> 0 | BN13: =SUM(AK13:BM13) -> 0 | CU13: =SUM(BP13:CT13) -> 0 | EA13: =SUM(CW13:DZ13) -> 0 | FH13: =SUM(EC13:FG13) -> 0 | GN13: =SUM(FJ13:GM13) -> 0 | HU13: =SUM(GP13:HT13) -> 0 | JB13: =SUM(HW13:JA13) -> 0 | KH13: =SUM(JD13:KG13) -> 0 | LO13: =SUM(KJ13:LN13) -> 0 | MU13: =SUM(LQ13:MT13) -> 0 | OB13: =SUM(MW13:OA13) -> 0 | OC13: =SUM(AI13,BN13,CU13,EA13,FH13,GN13,HU13,JB13,KH13,LO13,MU13,OB13) -> 0 | PJ13: =SUM(OE13:PI13) -> 0 | QO13: =SUM(PL13:QN13) -> 0 | RV13: =SUM(QQ13:RU13) -> 0 | RW13: =SUM(PJ13,QO13,RV13) -> 0
B14: Receita Operacional - VENDAS (VEÍCULO) | AI14: =SUM(D14:AH14) -> 0 | BN14: =SUM(AK14:BM14) -> 0 | CU14: =SUM(BP14:CT14) -> 0 | EA14: =SUM(CW14:DZ14) -> 0 | FH14: =SUM(EC14:FG14) -> 0 | GN14: =SUM(FJ14:GM14) -> 0 | HU14: =SUM(GP14:HT14) -> 0 | JB14: =SUM(HW14:JA14) -> 0 | KH14: =SUM(JD14:KG14) -> 0 | LO14: =SUM(KJ14:LN14) -> 0 | MU14: =SUM(LQ14:MT14) -> 0 | OB14: =SUM(MW14:OA14) -> 0 | OC14: =SUM(AI14,BN14,CU14,EA14,FH14,GN14,HU14,JB14,KH14,LO14,MU14,OB14) -> 0 | PJ14: =SUM(OE14:PI14) -> 0 | QO14: =SUM(PL14:QN14) -> 0 | RV14: =SUM(QQ14:RU14) -> 0 | RW14: =SUM(PJ14,QO14,RV14) -> 0
B15: Receita Operacional - VENDAS (FEE) | AI15: =SUM(D15:AH15) -> 0 | BN15: =SUM(AK15:BM15) -> 0 | CU15: =SUM(BP15:CT15) -> 0 | EA15: =SUM(CW15:DZ15) -> 0 | FH15: =SUM(EC15:FG15) -> 0 | GN15: =SUM(FJ15:GM15) -> 0 | HU15: =SUM(GP15:HT15) -> 0 | JB15: =SUM(HW15:JA15) -> 0 | KH15: =SUM(JD15:KG15) -> 0 | LO15: =SUM(KJ15:LN15) -> 0 | MU15: =SUM(LQ15:MT15) -> 0 | OB15: =SUM(MW15:OA15) -> 0 | OC15: =SUM(AI15,BN15,CU15,EA15,FH15,GN15,HU15,JB15,KH15,LO15,MU15,OB15) -> 0 | PJ15: =SUM(OE15:PI15) -> 0 | QO15: =SUM(PL15:QN15) -> 0 | RV15: =SUM(QQ15:RU15) -> 0 | RW15: =SUM(PJ15,QO15,RV15) -> 0
B16: Receita Operacional - VENDAS (CONSULTORIA) | AI16: =SUM(D16:AH16) -> 0 | BN16: =SUM(AK16:BM16) -> 0 | CU16: =SUM(BP16:CT16) -> 0 | EA16: =SUM(CW16:DZ16) -> 0 | FH16: =SUM(EC16:FG16) -> 0 | GN16: =SUM(FJ16:GM16) -> 0 | HU16: =SUM(GP16:HT16) -> 0 | JB16: =SUM(HW16:JA16) -> 0 | KH16: =SUM(JD16:KG16) -> 0 | LO16: =SUM(KJ16:LN16) -> 0 | MU16: =SUM(LQ16:MT16) -> 0 | OB16: =SUM(MW16:OA16) -> 0 | OC16: =SUM(AI16,BN16,CU16,EA16,FH16,GN16,HU16,JB16,KH16,LO16,MU16,OB16) -> 0 | PJ16: =SUM(OE16:PI16) -> 0 | QO16: =SUM(PL16:QN16) -> 0 | RV16: =SUM(QQ16:RU16) -> 0 | RW16: =SUM(PJ16,QO16,RV16) -> 0
B17: Receita Operacional - VENDAS (CONVERSACIONAL) | AI17: =SUM(D17:AH17) -> 0 | BN17: =SUM(AK17:BM17) -> 0 | CU17: =SUM(BP17:CT17) -> 0 | EA17: =SUM(CW17:DZ17) -> 0 | FH17: =SUM(EC17:FG17) -> 0 | GN17: =SUM(FJ17:GM17) -> 0 | HU17: =SUM(GP17:HT17) -> 0 | JB17: =SUM(HW17:JA17) -> 0 | KH17: =SUM(JD17:KG17) -> 0 | LO17: =SUM(KJ17:LN17) -> 0 | MU17: =SUM(LQ17:MT17) -> 0 | OB17: =SUM(MW17:OA17) -> 0 | OC17: =SUM(AI17,BN17,CU17,EA17,FH17,GN17,HU17,JB17,KH17,LO17,MU17,OB17) -> 0 | PJ17: =SUM(OE17:PI17) -> 0 | QO17: =SUM(PL17:QN17) -> 0 | RV17: =SUM(QQ17:RU17) -> 0 | RW17: =SUM(PJ17,QO17,RV17) -> 0
B18: Receita Operacional - VENDAS (MENSAGERIA) | AI18: =SUM(D18:AH18) -> 0 | BN18: =SUM(AK18:BM18) -> 0 | CU18: =SUM(BP18:CT18) -> 0 | EA18: =SUM(CW18:DZ18) -> 0 | FH18: =SUM(EC18:FG18) -> 0 | GN18: =SUM(FJ18:GM18) -> 0 | HU18: =SUM(GP18:HT18) -> 0 | JB18: =SUM(HW18:JA18) -> 0 | KH18: =SUM(JD18:KG18) -> 0 | LO18: =SUM(KJ18:LN18) -> 0 | MU18: =SUM(LQ18:MT18) -> 0 | OB18: =SUM(MW18:OA18) -> 0 | OC18: =SUM(AI18,BN18,CU18,EA18,FH18,GN18,HU18,JB18,KH18,LO18,MU18,OB18) -> 0 | PJ18: =SUM(OE18:PI18) -> 0 | QO18: =SUM(PL18:QN18) -> 0 | RV18: =SUM(QQ18:RU18) -> 0 | RW18: =SUM(PJ18,QO18,RV18) -> 0
B19: Receita Operacional - VENDAS (PARCEIROS) | AI19: =SUM(D19:AH19) -> 0 | BN19: =SUM(AK19:BM19) -> 0 | CU19: =SUM(BP19:CT19) -> 0 | EA19: =SUM(CW19:DZ19) -> 0 | FH19: =SUM(EC19:FG19) -> 0 | GN19: =SUM(FJ19:GM19) -> 0 | HU19: =SUM(GP19:HT19) -> 0 | JB19: =SUM(HW19:JA19) -> 0 | KH19: =SUM(JD19:KG19) -> 0 | LO19: =SUM(KJ19:LN19) -> 0 | MU19: =SUM(LQ19:MT19) -> 0 | OB19: =SUM(MW19:OA19) -> 0 | OC19: =SUM(AI19,BN19,CU19,EA19,FH19,GN19,HU19,JB19,KH19,LO19,MU19,OB19) -> 0 | PJ19: =SUM(OE19:PI19) -> 0 | QO19: =SUM(PL19:QN19) -> 0 | RV19: =SUM(QQ19:RU19) -> 0 | RW19: =SUM(PJ19,QO19,RV19) -> 0
B20: Receita Operacional - CREDITOS | AI20: =SUM(D20:AH20) -> 0 | BN20: =SUM(AK20:BM20) -> 0 | CU20: =SUM(BP20:CT20) -> 0 | EA20: =SUM(CW20:DZ20) -> 0 | FH20: =SUM(EC20:FG20) -> 0 | GN20: =SUM(FJ20:GM20) -> 0 | HU20: =SUM(GP20:HT20) -> 0 | JB20: =SUM(HW20:JA20) -> 0 | KH20: =SUM(JD20:KG20) -> 0 | LO20: =SUM(KJ20:LN20) -> 0 | MU20: =SUM(LQ20:MT20) -> 0 | OB20: =SUM(MW20:OA20) -> 0 | OC20: =SUM(AI20,BN20,CU20,EA20,FH20,GN20,HU20,JB20,KH20,LO20,MU20,OB20) -> 0 | PJ20: =SUM(OE20:PI20) -> 0 | QO20: =SUM(PL20:QN20) -> 0 | RV20: =SUM(QQ20:RU20) -> 0 | RW20: =SUM(PJ20,QO20,RV20) -> 0
B21: Receita Operacional - CREDITOS (VALOR COMISSÃO DAXX DO CRÉDITO) | AI21: =SUM(D21:AH21) -> 0 | BN21: =SUM(AK21:BM21) -> 0 | CU21: =SUM(BP21:CT21) -> 0 | EA21: =SUM(CW21:DZ21) -> 0 | FH21: =SUM(EC21:FG21) -> 0 | GN21: =SUM(FJ21:GM21) -> 0 | HU21: =SUM(GP21:HT21) -> 0 | JB21: =SUM(HW21:JA21) -> 0 | KH21: =SUM(JD21:KG21) -> 0 | LO21: =SUM(KJ21:LN21) -> 0 | MU21: =SUM(LQ21:MT21) -> 0 | OB21: =SUM(MW21:OA21) -> 0 | OC21: =SUM(AI21,BN21,CU21,EA21,FH21,GN21,HU21,JB21,KH21,LO21,MU21,OB21) -> 0 | PJ21: =SUM(OE21:PI21) -> 0 | QO21: =SUM(PL21:QN21) -> 0 | RV21: =SUM(QQ21:RU21) -> 0 | RW21: =SUM(PJ21,QO21,RV21) -> 0
B22: Receita Operacional - BV | AI22: =SUM(D22:AH22) -> 0 | BN22: =SUM(AK22:BM22) -> 0 | CU22: =SUM(BP22:CT22) -> 0 | EA22: =SUM(CW22:DZ22) -> 0 | FH22: =SUM(EC22:FG22) -> 0 | GN22: =SUM(FJ22:GM22) -> 0 | HU22: =SUM(GP22:HT22) -> 0 | JB22: =SUM(HW22:JA22) -> 0 | KH22: =SUM(JD22:KG22) -> 0 | LO22: =SUM(KJ22:LN22) -> 0 | MU22: =SUM(LQ22:MT22) -> 0 | OB22: =SUM(MW22:OA22) -> 0 | OC22: =SUM(AI22,BN22,CU22,EA22,FH22,GN22,HU22,JB22,KH22,LO22,MU22,OB22) -> 0 | PJ22: =SUM(OE22:PI22) -> 0 | QO22: =SUM(PL22:QN22) -> 0 | RV22: =SUM(QQ22:RU22) -> 0 | RW22: =SUM(PJ22,QO22,RV22) -> 0
B23: TOTAL RECEITAS | D23: =SUM(D4:D22) -> 0 | E23: =SUM(E4:E22) -> 0 | F23: =SUM(F4:F22) -> 0 | G23: =SUM(G4:G22) -> 0 | H23: =SUM(H4:H22) -> 1.76 | I23: =SUM(I4:I22) -> 0 | J23: =SUM(J4:J22) -> 0 | K23: =SUM(K4:K22) -> 0 | ... AI23: =SUM(AI4:AI22) -> 8.69 | AK23: =SUM(AK4:AK22) -> 0 | AL23: =SUM(AL4:AL22) -> 0 | AM23: =SUM(AM4:AM22) -> 0 | AN23: =SUM(AN4:AN22) -> 0 | AO23: =SUM(AO4:AO22) -> 20000 | AP23: =SUM(AP4:AP22) -> 0 | AQ23: =SUM(AQ4:AQ22) -> 0 | AR23: =SUM(AR4:AR22) -> 0 | ... BN23: =SUM(BN4:BN22) -> 20003.05 | BP23: =SUM(BP4:BP22) -> 0 | BQ23: =SUM(BQ4:BQ22) -> 0 | BR23: =SUM(BR4:BR22) -> 0 | BS23: =SUM(BS4:BS22) -> 0 | BT23: =SUM(BT4:BT22) -> 0.13 | BU23: =SUM(BU4:BU22) -> 0 | BV23: =SUM(BV4:BV22) -> 0 | BW23: =SUM(BW4:BW22) -> 0 | ... CU23: =SUM(CU4:CU22) -> 0.29 | CW23: =SUM(CW4:CW22) -> 0 | CX23: =SUM(CX4:CX22) -> 0 | CY23: =SUM(CY4:CY22) -> 0 | CZ23: =SUM(CZ4:CZ22) -> 0 | DA23: =SUM(DA4:DA22) -> 0 | DB23: =SUM(DB4:DB22) -> 0.27 | DC23: =SUM(DC4:DC22) -> 0 | DD23: =SUM(DD4:DD22) -> 0 | ... EA23: =SUM(EA4:EA22) -> 0.41 | EC23: =SUM(EC4:EC22) -> 0 | ED23: =SUM(ED4:ED22) -> 0 | EE23: =SUM(EE4:EE22) -> 0 | EF23: =SUM(EF4:EF22) -> 0 | EG23: =SUM(EG4:EG22) -> 0.4 | EH23: =SUM(EH4:EH22) -> 0 | EI23: =SUM(EI4:EI22) -> 0 | EJ23: =SUM(EJ4:EJ22) -> 0 | ... FH23: =SUM(FH4:FH22) -> 1.19 | FJ23: =SUM(FJ4:FJ22) -> 0 | FK23: =SUM(FK4:FK22) -> 0 | FL23: =SUM(FL4:FL22) -> 0 | FM23: =SUM(FM4:FM22) -> 0 | FN23: =SUM(FN4:FN22) -> 0 | FO23: =SUM(FO4:FO22) -> 0 | FP23: =SUM(FP4:FP22) -> 0 | FQ23: =SUM(FQ4:FQ22) -> 0 | ... GN23: =SUM(GN4:GN22) -> 0 | GP23: =SUM(GP4:GP22) -> 0 | GQ23: =SUM(GQ4:GQ22) -> 0 | GR23: =SUM(GR4:GR22) -> 0 | GS23: =SUM(GS4:GS22) -> 0 | GT23: =SUM(GT4:GT22) -> 0 | GU23: =SUM(GU4:GU22) -> 0 | GV23: =SUM(GV4:GV22) -> 0 | GW23: =SUM(GW4:GW22) -> 0 | ... HU23: =SUM(HU4:HU22) -> 0 | HW23: =SUM(HW4:HW22) -> 0 | HX23: =SUM(HX4:HX22) -> 0 | HY23: =SUM(HY4:HY22) -> 0 | HZ23: =SUM(HZ4:HZ22) -> 0 | IA23: =SUM(IA4:IA22) -> 0 | IB23: =SUM(IB4:IB22) -> 0 | IC23: =SUM(IC4:IC22) -> 0 | ID23: =SUM(ID4:ID22) -> 0 | ... JB23: =SUM(JB4:JB22) -> 0 | JD23: =SUM(JD4:JD22) -> 0 | JE23: =SUM(JE4:JE22) -> 0 | JF23: =SUM(JF4:JF22) -> 0 | JG23: =SUM(JG4:JG22) -> 0 | JH23: =SUM(JH4:JH22) -> 0 | JI23: =SUM(JI4:JI22) -> 0 | JJ23: =SUM(JJ4:JJ22) -> 0 | JK23: =SUM(JK4:JK22) -> 0 | ... KH23: =SUM(KH4:KH22) -> 0 | KJ23: =SUM(KJ4:KJ22) -> 0 | KK23: =SUM(KK4:KK22) -> 0 | KL23: =SUM(KL4:KL22) -> 0 | KM23: =SUM(KM4:KM22) -> 0 | KN23: =SUM(KN4:KN22) -> 0 | KO23: =SUM(KO4:KO22) -> 0 | KP23: =SUM(KP4:KP22) -> 0 | KQ23: =SUM(KQ4:KQ22) -> 0 | ... LO23: =SUM(LO4:LO22) -> 0 | LQ23: =SUM(LQ4:LQ22) -> 0 | LR23: =SUM(LR4:LR22) -> 0 | LS23: =SUM(LS4:LS22) -> 0 | LT23: =SUM(LT4:LT22) -> 0 | LU23: =SUM(LU4:LU22) -> 0 | LV23: =SUM(LV4:LV22) -> 0 | LW23: =SUM(LW4:LW22) -> 0 | LX23: =SUM(LX4:LX22) -> 0 | ... MU23: =SUM(MU4:MU22) -> 0 | MW23: =SUM(MW4:MW22) -> 0 | MX23: =SUM(MX4:MX22) -> 0 | MY23: =SUM(MY4:MY22) -> 0 | MZ23: =SUM(MZ4:MZ22) -> 0 | NA23: =SUM(NA4:NA22) -> 0 | NB23: =SUM(NB4:NB22) -> 0 | NC23: =SUM(NC4:NC22) -> 0 | ND23: =SUM(ND4:ND22) -> 0 | ... OB23: =SUM(OB4:OB22) -> 0 | OC23: =SUM(AI23,BN23,CU23,EA23,FH23,GN23,HU23,JB23,KH23,LO23,MU23,OB23) -> 20013.63 | OE23: =SUM(OE4:OE22) -> 0 | OF23: =SUM(OF4:OF22) -> 0 | OG23: =SUM(OG4:OG22) -> 0 | OH23: =SUM(OH4:OH22) -> 0 | OI23: =SUM(OI4:OI22) -> 0 | OJ23: =SUM(OJ4:OJ22) -> 0 | OK23: =SUM(OK4:OK22) -> 0 | OL23: =SUM(OL4:OL22) -> 0 | ... PJ23: =SUM(PJ4:PJ22) -> 0 | PL23: =SUM(PL4:PL22) -> 0 | PM23: =SUM(PM4:PM22) -> 0 | PN23: =SUM(PN4:PN22) -> 0 | PO23: =SUM(PO4:PO22) -> 0 | PP23: =SUM(PP4:PP22) -> 0 | PQ23: =SUM(PQ4:PQ22) -> 0 | PR23: =SUM(PR4:PR22) -> 0 | PS23: =SUM(PS4:PS22) -> 0 | ... QO23: =SUM(QO4:QO22) -> 0 | QQ23: =SUM(QQ4:QQ22) -> 0 | QR23: =SUM(QR4:QR22) -> 0 | QS23: =SUM(QS4:QS22) -> 0 | QT23: =SUM(QT4:QT22) -> 0 | QU23: =SUM(QU4:QU22) -> 0 | QV23: =SUM(QV4:QV22) -> 0 | QW23: =SUM(QW4:QW22) -> 0 | QX23: =SUM(QX4:QX22) -> 0 | ... RV23: =SUM(RV4:RV22) -> 0 | RW23: =SUM(PJ23,QO23,RV23) -> 0
B24: COMPRA CRÉDITO EM VEÍCULO | AI24: =SUM(D24:AH24) -> 0 | BN24: =SUM(AK24:BM24) -> 0 | CU24: =SUM(BP24:CT24) -> 0 | EA24: =SUM(CW24:DZ24) -> 0 | FH24: =SUM(EC24:FG24) -> 0 | GN24: =SUM(FJ24:GM24) -> 0 | HU24: =SUM(GP24:HT24) -> 0 | JB24: =SUM(HW24:JA24) -> 0 | KH24: =SUM(JD24:KG24) -> 0 | LO24: =SUM(KJ24:LN24) -> 0 | MU24: =SUM(LQ24:MT24) -> 0 | OB24: =SUM(MW24:OA24) -> 0 | OC24: =SUM(AI24,BN24,CU24,EA24,FH24,GN24,HU24,JB24,KH24,LO24,MU24,OB24) -> 0 | PJ24: =SUM(OE24:PI24) -> 0 | QO24: =SUM(PL24:QN24) -> 0 | RV24: =SUM(QQ24:RU24) -> 0 | RW24: =SUM(PJ24,QO24,RV24) -> 0
B25: CUSTO REPASSE COM VEÍCULO | AI25: =SUM(D25:AH25) -> 0 | BN25: =SUM(AK25:BM25) -> 0 | CU25: =SUM(BP25:CT25) -> 0 | EA25: =SUM(CW25:DZ25) -> 0 | FH25: =SUM(EC25:FG25) -> 0 | GN25: =SUM(FJ25:GM25) -> 0 | HU25: =SUM(GP25:HT25) -> 0 | JB25: =SUM(HW25:JA25) -> 0 | KH25: =SUM(JD25:KG25) -> 0 | LO25: =SUM(KJ25:LN25) -> 0 | MU25: =SUM(LQ25:MT25) -> 0 | OB25: =SUM(MW25:OA25) -> 0 | OC25: =SUM(AI25,BN25,CU25,EA25,FH25,GN25,HU25,JB25,KH25,LO25,MU25,OB25) -> 0 | PJ25: =SUM(OE25:PI25) -> 0 | QO25: =SUM(PL25:QN25) -> 0 | RV25: =SUM(QQ25:RU25) -> 0 | RW25: =SUM(PJ25,QO25,RV25) -> 0
A27: 1 | B27: IMPOSTOS E TRIBUTOS SOBRE RECEITA DE VENDAS
B28: Simples Nacional | AI28: =SUM(D28:AH28) -> 0 | BN28: =SUM(AK28:BM28) -> 0 | CU28: =SUM(BP28:CT28) -> 0 | EA28: =SUM(CW28:DZ28) -> 0 | FH28: =SUM(EC28:FG28) -> 0 | GN28: =SUM(FJ28:GM28) -> 0 | HU28: =SUM(GP28:HT28) -> 0 | JB28: =SUM(HW28:JA28) -> 0 | KH28: =SUM(JD28:KG28) -> 0 | LO28: =SUM(KJ28:LN28) -> 0 | MU28: =SUM(LQ28:MT28) -> 0 | OB28: =SUM(MW28:OA28) -> 0 | OC28: =SUM(AI28,BN28,CU28,EA28,FH28,GN28,HU28,JB28,KH28,LO28,MU28,OB28) -> 0 | PJ28: =SUM(OE28:PI28) -> 0 | QO28: =SUM(PL28:QN28) -> 0 | RV28: =SUM(QQ28:RU28) -> 0 | RW28: =SUM(PJ28,QO28,RV28) -> 0
B29: PIS | AI29: =SUM(D29:AH29) -> 0 | BN29: =SUM(AK29:BM29) -> 0 | CU29: =SUM(BP29:CT29) -> 0 | EA29: =SUM(CW29:DZ29) -> 0 | FH29: =SUM(EC29:FG29) -> 0 | GN29: =SUM(FJ29:GM29) -> 0 | HU29: =SUM(GP29:HT29) -> 0 | JB29: =SUM(HW29:JA29) -> 0 | KH29: =SUM(JD29:KG29) -> 0 | LO29: =SUM(KJ29:LN29) -> 0 | MU29: =SUM(LQ29:MT29) -> 0 | OB29: =SUM(MW29:OA29) -> 0 | OC29: =SUM(AI29,BN29,CU29,EA29,FH29,GN29,HU29,JB29,KH29,LO29,MU29,OB29) -> 0 | PJ29: =SUM(OE29:PI29) -> 0 | QO29: =SUM(PL29:QN29) -> 0 | RV29: =SUM(QQ29:RU29) -> 0 | RW29: =SUM(PJ29,QO29,RV29) -> 0
B30: COFINS | AI30: =SUM(D30:AH30) -> 0 | BN30: =SUM(AK30:BM30) -> 0 | CU30: =SUM(BP30:CT30) -> 0 | EA30: =SUM(CW30:DZ30) -> 0 | FH30: =SUM(EC30:FG30) -> 0 | GN30: =SUM(FJ30:GM30) -> 0 | HU30: =SUM(GP30:HT30) -> 0 | JB30: =SUM(HW30:JA30) -> 0 | KH30: =SUM(JD30:KG30) -> 0 | LO30: =SUM(KJ30:LN30) -> 0 | MU30: =SUM(LQ30:MT30) -> 0 | OB30: =SUM(MW30:OA30) -> 0 | OC30: =SUM(AI30,BN30,CU30,EA30,FH30,GN30,HU30,JB30,KH30,LO30,MU30,OB30) -> 0 | PJ30: =SUM(OE30:PI30) -> 0 | QO30: =SUM(PL30:QN30) -> 0 | RV30: =SUM(QQ30:RU30) -> 0 | RW30: =SUM(PJ30,QO30,RV30) -> 0
B31: ISS | AI31: =SUM(D31:AH31) -> 0 | BN31: =SUM(AK31:BM31) -> 0 | CU31: =SUM(BP31:CT31) -> 0 | EA31: =SUM(CW31:DZ31) -> 0 | FH31: =SUM(EC31:FG31) -> 0 | GN31: =SUM(FJ31:GM31) -> 0 | HU31: =SUM(GP31:HT31) -> 0 | JB31: =SUM(HW31:JA31) -> 0 | KH31: =SUM(JD31:KG31) -> 0 | LO31: =SUM(KJ31:LN31) -> 0 | MU31: =SUM(LQ31:MT31) -> 0 | OB31: =SUM(MW31:OA31) -> 0 | OC31: =SUM(AI31,BN31,CU31,EA31,FH31,GN31,HU31,JB31,KH31,LO31,MU31,OB31) -> 0 | PJ31: =SUM(OE31:PI31) -> 0 | QO31: =SUM(PL31:QN31) -> 0 | RV31: =SUM(QQ31:RU31) -> 0 | RW31: =SUM(PJ31,QO31,RV31) -> 0
B32: CSLL | AI32: =SUM(D32:AH32) -> 0 | BN32: =SUM(AK32:BM32) -> 0 | CU32: =SUM(BP32:CT32) -> 0 | EA32: =SUM(CW32:DZ32) -> 0 | FH32: =SUM(EC32:FG32) -> 0 | GN32: =SUM(FJ32:GM32) -> 0 | HU32: =SUM(GP32:HT32) -> 0 | JB32: =SUM(HW32:JA32) -> 0 | KH32: =SUM(JD32:KG32) -> 0 | LO32: =SUM(KJ32:LN32) -> 0 | MU32: =SUM(LQ32:MT32) -> 0 | OB32: =SUM(MW32:OA32) -> 0 | OC32: =SUM(AI32,BN32,CU32,EA32,FH32,GN32,HU32,JB32,KH32,LO32,MU32,OB32) -> 0 | PJ32: =SUM(OE32:PI32) -> 0 | QO32: =SUM(PL32:QN32) -> 0 | RV32: =SUM(QQ32:RU32) -> 0 | RW32: =SUM(PJ32,QO32,RV32) -> 0
B33: IRPJ | AI33: =SUM(D33:AH33) -> 0 | BN33: =SUM(AK33:BM33) -> 0 | CU33: =SUM(BP33:CT33) -> 0 | EA33: =SUM(CW33:DZ33) -> 0 | FH33: =SUM(EC33:FG33) -> 0 | GN33: =SUM(FJ33:GM33) -> 0 | HU33: =SUM(GP33:HT33) -> 0 | JB33: =SUM(HW33:JA33) -> 0 | KH33: =SUM(JD33:KG33) -> 0 | LO33: =SUM(KJ33:LN33) -> 0 | MU33: =SUM(LQ33:MT33) -> 0 | OB33: =SUM(MW33:OA33) -> 0 | OC33: =SUM(AI33,BN33,CU33,EA33,FH33,GN33,HU33,JB33,KH33,LO33,MU33,OB33) -> 0 | PJ33: =SUM(OE33:PI33) -> 0 | QO33: =SUM(PL33:QN33) -> 0 | RV33: =SUM(QQ33:RU33) -> 0 | RW33: =SUM(PJ33,QO33,RV33) -> 0
B34: OUTRAS DESPESAS FISCAIS | W34: 14.01 | AI34: =SUM(D34:AH34) -> 14.01 | AT34: 535.54 | BD34: 14.01 | BN34: =SUM(AK34:BM34) -> 549.55 | CI34: 14.01 | CU34: =SUM(BP34:CT34) -> 14.01 | DP34: 14.01 | EA34: =SUM(CW34:DZ34) -> 14.01 | EV34: 14.01 | FH34: =SUM(EC34:FG34) -> 14.01 | FU34: =535.62 -> 535.62 | GC34: 14.01 | GN34: =SUM(FJ34:GM34) -> 549.63 | HI34: 14.01 | HU34: =SUM(GP34:HT34) -> 14.01 | IP34: 14.01 | JB34: =SUM(HW34:JA34) -> 14.01 | JW34: 14.01 | KH34: =SUM(JD34:KG34) -> 14.01 | LC34: 14.01 | LO34: =SUM(KJ34:LN34) -> 14.01 | MJ34: 14.01 | MU34: =SUM(LQ34:MT34) -> 14.01 | NP34: 14.01 | OB34: =SUM(MW34:OA34) -> 14.01 | OC34: =SUM(AI34,BN34,CU34,EA34,FH34,GN34,HU34,JB34,KH34,LO34,MU34,OB34) -> 1239.28 | PJ34: =SUM(OE34:PI34) -> 0 | QO34: =SUM(PL34:QN34) -> 0 | RV34: =SUM(QQ34:RU34) -> 0 | RW34: =SUM(PJ34,QO34,RV34) -> 0
B35: TOTAL IMPOSTOS E TRIBUTOS SOBRE VENDA | D35: =SUM(D28:D34) -> 0 | E35: =SUM(E28:E34) -> 0 | F35: =SUM(F28:F34) -> 0 | G35: =SUM(G28:G34) -> 0 | H35: =SUM(H28:H34) -> 0 | I35: =SUM(I28:I34) -> 0 | J35: =SUM(J28:J34) -> 0 | K35: =SUM(K28:K34) -> 0 | ... AI35: =SUM(AI28:AI34) -> 14.01 | AK35: =SUM(AK28:AK34) -> 0 | AL35: =SUM(AL28:AL34) -> 0 | AM35: =SUM(AM28:AM34) -> 0 | AN35: =SUM(AN28:AN34) -> 0 | AO35: =SUM(AO28:AO34) -> 0 | AP35: =SUM(AP28:AP34) -> 0 | AQ35: =SUM(AQ28:AQ34) -> 0 | AR35: =SUM(AR28:AR34) -> 0 | ... BN35: =SUM(BN28:BN34) -> 549.55 | BP35: =SUM(BP28:BP34) -> 0 | BQ35: =SUM(BQ28:BQ34) -> 0 | BR35: =SUM(BR28:BR34) -> 0 | BS35: =SUM(BS28:BS34) -> 0 | BT35: =SUM(BT28:BT34) -> 0 | BU35: =SUM(BU28:BU34) -> 0 | BV35: =SUM(BV28:BV34) -> 0 | BW35: =SUM(BW28:BW34) -> 0 | ... CU35: =SUM(CU28:CU34) -> 14.01 | CW35: =SUM(CW28:CW34) -> 0 | CX35: =SUM(CX28:CX34) -> 0 | CY35: =SUM(CY28:CY34) -> 0 | CZ35: =SUM(CZ28:CZ34) -> 0 | DA35: =SUM(DA28:DA34) -> 0 | DB35: =SUM(DB28:DB34) -> 0 | DC35: =SUM(DC28:DC34) -> 0 | DD35: =SUM(DD28:DD34) -> 0 | ... EA35: =SUM(EA28:EA34) -> 14.01 | EC35: =SUM(EC28:EC34) -> 0 | ED35: =SUM(ED28:ED34) -> 0 | EE35: =SUM(EE28:EE34) -> 0 | EF35: =SUM(EF28:EF34) -> 0 | EG35: =SUM(EG28:EG34) -> 0 | EH35: =SUM(EH28:EH34) -> 0 | EI35: =SUM(EI28:EI34) -> 0 | EJ35: =SUM(EJ28:EJ34) -> 0 | ... FH35: =SUM(FH28:FH34) -> 14.01 | FJ35: =SUM(FJ28:FJ34) -> 0 | FK35: =SUM(FK28:FK34) -> 0 | FL35: =SUM(FL28:FL34) -> 0 | FM35: =SUM(FM28:FM34) -> 0 | FN35: =SUM(FN28:FN34) -> 0 | FO35: =SUM(FO28:FO34) -> 0 | FP35: =SUM(FP28:FP34) -> 0 | FQ35: =SUM(FQ28:FQ34) -> 0 | ... GN35: =SUM(GN28:GN34) -> 549.63 | GP35: =SUM(GP28:GP34) -> 0 | GQ35: =SUM(GQ28:GQ34) -> 0 | GR35: =SUM(GR28:GR34) -> 0 | GS35: =SUM(GS28:GS34) -> 0 | GT35: =SUM(GT28:GT34) -> 0 | GU35: =SUM(GU28:GU34) -> 0 | GV35: =SUM(GV28:GV34) -> 0 | GW35: =SUM(GW28:GW34) -> 0 | ... HU35: =SUM(HU28:HU34) -> 14.01 | HW35: =SUM(HW28:HW34) -> 0 | HX35: =SUM(HX28:HX34) -> 0 | HY35: =SUM(HY28:HY34) -> 0 | HZ35: =SUM(HZ28:HZ34) -> 0 | IA35: =SUM(IA28:IA34) -> 0 | IB35: =SUM(IB28:IB34) -> 0 | IC35: =SUM(IC28:IC34) -> 0 | ID35: =SUM(ID28:ID34) -> 0 | ... JB35: =SUM(JB28:JB34) -> 14.01 | JD35: =SUM(JD28:JD34) -> 0 | JE35: =SUM(JE28:JE34) -> 0 | JF35: =SUM(JF28:JF34) -> 0 | JG35: =SUM(JG28:JG34) -> 0 | JH35: =SUM(JH28:JH34) -> 0 | JI35: =SUM(JI28:JI34) -> 0 | JJ35: =SUM(JJ28:JJ34) -> 0 | JK35: =SUM(JK28:JK34) -> 0 | ... KH35: =SUM(KH28:KH34) -> 14.01 | KJ35: =SUM(KJ28:KJ34) -> 0 | KK35: =SUM(KK28:KK34) -> 0 | KL35: =SUM(KL28:KL34) -> 0 | KM35: =SUM(KM28:KM34) -> 0 | KN35: =SUM(KN28:KN34) -> 0 | KO35: =SUM(KO28:KO34) -> 0 | KP35: =SUM(KP28:KP34) -> 0 | KQ35: =SUM(KQ28:KQ34) -> 0 | ... LO35: =SUM(LO28:LO34) -> 14.01 | LQ35: =SUM(LQ28:LQ34) -> 0 | LR35: =SUM(LR28:LR34) -> 0 | LS35: =SUM(LS28:LS34) -> 0 | LT35: =SUM(LT28:LT34) -> 0 | LU35: =SUM(LU28:LU34) -> 0 | LV35: =SUM(LV28:LV34) -> 0 | LW35: =SUM(LW28:LW34) -> 0 | LX35: =SUM(LX28:LX34) -> 0 | ... MU35: =SUM(MU28:MU34) -> 14.01 | MW35: =SUM(MW28:MW34) -> 0 | MX35: =SUM(MX28:MX34) -> 0 | MY35: =SUM(MY28:MY34) -> 0 | MZ35: =SUM(MZ28:MZ34) -> 0 | NA35: =SUM(NA28:NA34) -> 0 | NB35: =SUM(NB28:NB34) -> 0 | NC35: =SUM(NC28:NC34) -> 0 | ND35: =SUM(ND28:ND34) -> 0 | ... OB35: =SUM(OB28:OB34) -> 14.01 | OC35: =SUM(AI35,BN35,CU35,EA35,FH35,GN35,HU35,JB35,KH35,LO35,MU35,OB35) -> 1239.28 | OE35: =SUM(OE28:OE34) -> 0 | OF35: =SUM(OF28:OF34) -> 0 | OG35: =SUM(OG28:OG34) -> 0 | OH35: =SUM(OH28:OH34) -> 0 | OI35: =SUM(OI28:OI34) -> 0 | OJ35: =SUM(OJ28:OJ34) -> 0 | OK35: =SUM(OK28:OK34) -> 0 | OL35: =SUM(OL28:OL34) -> 0 | ... PJ35: =SUM(PJ28:PJ34) -> 0 | PL35: =SUM(PL28:PL34) -> 0 | PM35: =SUM(PM28:PM34) -> 0 | PN35: =SUM(PN28:PN34) -> 0 | PO35: =SUM(PO28:PO34) -> 0 | PP35: =SUM(PP28:PP34) -> 0 | PQ35: =SUM(PQ28:PQ34) -> 0 | PR35: =SUM(PR28:PR34) -> 0 | PS35: =SUM(PS28:PS34) -> 0 | ... QO35: =SUM(QO28:QO34) -> 0 | QQ35: =SUM(QQ28:QQ34) -> 0 | QR35: =SUM(QR28:QR34) -> 0 | QS35: =SUM(QS28:QS34) -> 0 | QT35: =SUM(QT28:QT34) -> 0 | QU35: =SUM(QU28:QU34) -> 0 | QV35: =SUM(QV28:QV34) -> 0 | QW35: =SUM(QW28:QW34) -> 0 | QX35: =SUM(QX28:QX34) -> 0 | ... RV35: =SUM(RV28:RV34) -> 0 | RW35: =SUM(PJ35,QO35,RV35) -> 0
A37: 1 | B37: DESPESAS COM PESSOAL
B38: Folha de Pagamento (PJ) | AI38: =SUM(D38:AH38) -> 0 | BN38: =SUM(AK38:BM38) -> 0 | CU38: =SUM(BP38:CT38) -> 0 | EA38: =SUM(CW38:DZ38) -> 0 | FH38: =SUM(EC38:FG38) -> 0 | GN38: =SUM(FJ38:GM38) -> 0 | HU38: =SUM(GP38:HT38) -> 0 | JB38: =SUM(HW38:JA38) -> 0 | KH38: =SUM(JD38:KG38) -> 0 | LO38: =SUM(KJ38:LN38) -> 0 | MU38: =SUM(LQ38:MT38) -> 0 | OB38: =SUM(MW38:OA38) -> 0 | OC38: =SUM(AI38,BN38,CU38,EA38,FH38,GN38,HU38,JB38,KH38,LO38,MU38,OB38) -> 0 | PJ38: =SUM(OE38:PI38) -> 0 | QO38: =SUM(PL38:QN38) -> 0 | RV38: =SUM(QQ38:RU38) -> 0 | RW38: =SUM(PJ38,QO38,RV38) -> 0
B39: Folha de Pagamento (ESTAGIÁRIO) | AI39: =SUM(D39:AH39) -> 0 | BN39: =SUM(AK39:BM39) -> 0 | CU39: =SUM(BP39:CT39) -> 0 | EA39: =SUM(CW39:DZ39) -> 0 | FH39: =SUM(EC39:FG39) -> 0 | GN39: =SUM(FJ39:GM39) -> 0 | HU39: =SUM(GP39:HT39) -> 0 | JB39: =SUM(HW39:JA39) -> 0 | KH39: =SUM(JD39:KG39) -> 0 | LO39: =SUM(KJ39:LN39) -> 0 | MU39: =SUM(LQ39:MT39) -> 0 | OB39: =SUM(MW39:OA39) -> 0 | OC39: =SUM(AI39,BN39,CU39,EA39,FH39,GN39,HU39,JB39,KH39,LO39,MU39,OB39) -> 0 | PJ39: =SUM(OE39:PI39) -> 0 | QO39: =SUM(PL39:QN39) -> 0 | RV39: =SUM(QQ39:RU39) -> 0 | RW39: =SUM(PJ39,QO39,RV39) -> 0
B40: 13º Salário | AI40: =SUM(D40:AH40) -> 0 | BN40: =SUM(AK40:BM40) -> 0 | CU40: =SUM(BP40:CT40) -> 0 | EA40: =SUM(CW40:DZ40) -> 0 | FH40: =SUM(EC40:FG40) -> 0 | GN40: =SUM(FJ40:GM40) -> 0 | HU40: =SUM(GP40:HT40) -> 0 | JB40: =SUM(HW40:JA40) -> 0 | KH40: =SUM(JD40:KG40) -> 0 | LO40: =SUM(KJ40:LN40) -> 0 | MU40: =SUM(LQ40:MT40) -> 0 | OB40: =SUM(MW40:OA40) -> 0 | OC40: =SUM(AI40,BN40,CU40,EA40,FH40,GN40,HU40,JB40,KH40,LO40,MU40,OB40) -> 0 | PJ40: =SUM(OE40:PI40) -> 0 | QO40: =SUM(PL40:QN40) -> 0 | RV40: =SUM(QQ40:RU40) -> 0 | RW40: =SUM(PJ40,QO40,RV40) -> 0
B41: Vale Refeição | AI41: =SUM(D41:AH41) -> 0 | BN41: =SUM(AK41:BM41) -> 0 | CU41: =SUM(BP41:CT41) -> 0 | EA41: =SUM(CW41:DZ41) -> 0 | FH41: =SUM(EC41:FG41) -> 0 | GN41: =SUM(FJ41:GM41) -> 0 | HU41: =SUM(GP41:HT41) -> 0 | JB41: =SUM(HW41:JA41) -> 0 | KH41: =SUM(JD41:KG41) -> 0 | LO41: =SUM(KJ41:LN41) -> 0 | MU41: =SUM(LQ41:MT41) -> 0 | OB41: =SUM(MW41:OA41) -> 0 | OC41: =SUM(AI41,BN41,CU41,EA41,FH41,GN41,HU41,JB41,KH41,LO41,MU41,OB41) -> 0 | PJ41: =SUM(OE41:PI41) -> 0 | QO41: =SUM(PL41:QN41) -> 0 | RV41: =SUM(QQ41:RU41) -> 0 | RW41: =SUM(PJ41,QO41,RV41) -> 0
B42: Vale Transporte | AI42: =SUM(D42:AH42) -> 0 | BN42: =SUM(AK42:BM42) -> 0 | CU42: =SUM(BP42:CT42) -> 0 | EA42: =SUM(CW42:DZ42) -> 0 | FH42: =SUM(EC42:FG42) -> 0 | GN42: =SUM(FJ42:GM42) -> 0 | HU42: =SUM(GP42:HT42) -> 0 | JB42: =SUM(HW42:JA42) -> 0 | KH42: =SUM(JD42:KG42) -> 0 | LO42: =SUM(KJ42:LN42) -> 0 | MU42: =SUM(LQ42:MT42) -> 0 | OB42: =SUM(MW42:OA42) -> 0 | OC42: =SUM(AI42,BN42,CU42,EA42,FH42,GN42,HU42,JB42,KH42,LO42,MU42,OB42) -> 0 | PJ42: =SUM(OE42:PI42) -> 0 | QO42: =SUM(PL42:QN42) -> 0 | RV42: =SUM(QQ42:RU42) -> 0 | RW42: =SUM(PJ42,QO42,RV42) -> 0
B43: Assistência Médica | AI43: =SUM(D43:AH43) -> 0 | BN43: =SUM(AK43:BM43) -> 0 | CU43: =SUM(BP43:CT43) -> 0 | EA43: =SUM(CW43:DZ43) -> 0 | FH43: =SUM(EC43:FG43) -> 0 | GN43: =SUM(FJ43:GM43) -> 0 | HU43: =SUM(GP43:HT43) -> 0 | JB43: =SUM(HW43:JA43) -> 0 | KH43: =SUM(JD43:KG43) -> 0 | LO43: =SUM(KJ43:LN43) -> 0 | MU43: =SUM(LQ43:MT43) -> 0 | OB43: =SUM(MW43:OA43) -> 0 | OC43: =SUM(AI43,BN43,CU43,EA43,FH43,GN43,HU43,JB43,KH43,LO43,MU43,OB43) -> 0 | PJ43: =SUM(OE43:PI43) -> 0 | QO43: =SUM(PL43:QN43) -> 0 | RV43: =SUM(QQ43:RU43) -> 0 | RW43: =SUM(PJ43,QO43,RV43) -> 0
...

Sheet SALDOS
C2: DAXX MIDIA PE
A3: DATA | C3: SALDO FINAL CC | D3: SALDO FINAL CDB | E3: SALDO FINAL TRUST DI | F3: C/ CORRENTE + APLICAÇÃO
A4: ='DAXX MIDIA PE'!$D1 -> 46023 | C4: ='DAXX MIDIA PE'!$D255 -> 3236.1 | D4: ='DAXX MIDIA PE'!$D261 -> 0 | E4: ='DAXX MIDIA PE'!$D267 -> 0 | F4: ='DAXX MIDIA PE'!$D269 -> 3236.1
A5: ='DAXX MIDIA PE'!$E1 -> 46024 | C5: ='DAXX MIDIA PE'!$E255 -> 3236.1 | D5: ='DAXX MIDIA PE'!$E261 -> 0 | E5: ='DAXX MIDIA PE'!$E267 -> 0 | F5: ='DAXX MIDIA PE'!$E269 -> 3236.1
A6: ='DAXX MIDIA PE'!$F1 -> 46025 | C6: ='DAXX MIDIA PE'!$F255 -> 3236.1 | D6: ='DAXX MIDIA PE'!$F261 -> 0 | E6: ='DAXX MIDIA PE'!$F267 -> 0 | F6: ='DAXX MIDIA PE'!$F269 -> 3236.1
A7: ='DAXX MIDIA PE'!$G1 -> 46026 | C7: ='DAXX MIDIA PE'!$G255 -> 3236.1 | D7: ='DAXX MIDIA PE'!$G261 -> 0 | E7: ='DAXX MIDIA PE'!$G267 -> 0 | F7: ='DAXX MIDIA PE'!$G269 -> 3236.1
A8: ='DAXX MIDIA PE'!$H1 -> 46027 | C8: ='DAXX MIDIA PE'!$H255 -> 2478.86 | D8: ='DAXX MIDIA PE'!$H261 -> 0 | E8: ='DAXX MIDIA PE'!$H267 -> 0 | F8: ='DAXX MIDIA PE'!$H269 -> 2478.86
A9: ='DAXX MIDIA PE'!$I1 -> 46028 | C9: ='DAXX MIDIA PE'!$I255 -> 2478.86 | D9: ='DAXX MIDIA PE'!$I261 -> 0 | E9: ='DAXX MIDIA PE'!$I267 -> 0 | F9: ='DAXX MIDIA PE'!$I269 -> 2478.86
A10: ='DAXX MIDIA PE'!$J1 -> 46029 | C10: ='DAXX MIDIA PE'!$J255 -> 2478.86 | D10: ='DAXX MIDIA PE'!$J261 -> 0 | E10: ='DAXX MIDIA PE'!$J267 -> 0 | F10: ='DAXX MIDIA PE'!$J269 -> 2478.86
A11: ='DAXX MIDIA PE'!$K1 -> 46030 | C11: ='DAXX MIDIA PE'!$K255 -> 2478.86 | D11: ='DAXX MIDIA PE'!$K261 -> 0 | E11: ='DAXX MIDIA PE'!$K267 -> 0 | F11: ='DAXX MIDIA PE'!$K269 -> 2478.86
A12: ='DAXX MIDIA PE'!$L1 -> 46031 | C12: ='DAXX MIDIA PE'!$L255 -> 2478.86 | D12: ='DAXX MIDIA PE'!$L261 -> 0 | E12: ='DAXX MIDIA PE'!$L267 -> 0 | F12: ='DAXX MIDIA PE'!$L269 -> 2478.86
A13: ='DAXX MIDIA PE'!$M1 -> 46032 | C13: ='DAXX MIDIA PE'!$M255 -> 2478.86 | D13: ='DAXX MIDIA PE'!$M261 -> 0 | E13: ='DAXX MIDIA PE'!$M267 -> 0 | F13: ='DAXX MIDIA PE'!$M269 -> 2478.86
A14: ='DAXX MIDIA PE'!$N1 -> 46033 | C14: ='DAXX MIDIA PE'!$N255 -> 2478.86 | D14: ='DAXX MIDIA PE'!$N261 -> 0 | E14: ='DAXX MIDIA PE'!$N267 -> 0 | F14: ='DAXX MIDIA PE'!$N269 -> 2478.86
A15: ='DAXX MIDIA PE'!$O1 -> 46034 | C15: ='DAXX MIDIA PE'!$O255 -> 2478.86 | D15: ='DAXX MIDIA PE'!$O261 -> 0 | E15: ='DAXX MIDIA PE'!$O267 -> 0 | F15: ='DAXX MIDIA PE'!$O269 -> 2478.86
A16: ='DAXX MIDIA PE'!$P1 -> 46035 | C16: ='DAXX MIDIA PE'!$P255 -> 2478.86 | D16: ='DAXX MIDIA PE'!$P261 -> 0 | E16: ='DAXX MIDIA PE'!$P267 -> 0 | F16: ='DAXX MIDIA PE'!$P269 -> 2478.86
A17: ='DAXX MIDIA PE'!$Q1 -> 46036 | C17: ='DAXX MIDIA PE'!$Q255 -> 1366.62 | D17: ='DAXX MIDIA PE'!$Q261 -> 0 | E17: ='DAXX MIDIA PE'!$Q267 -> 0 | F17: ='DAXX MIDIA PE'!$Q269 -> 1366.62
A18: ='DAXX MIDIA PE'!$R1 -> 46037 | C18: ='DAXX MIDIA PE'!$R255 -> 1366.62 | D18: ='DAXX MIDIA PE'!$R261 -> 0 | E18: ='DAXX MIDIA PE'!$R267 -> 0 | F18: ='DAXX MIDIA PE'!$R269 -> 1366.62
A19: ='DAXX MIDIA PE'!$S1 -> 46038 | C19: ='DAXX MIDIA PE'!$S255 -> 1366.62 | D19: ='DAXX MIDIA PE'!$S261 -> 0 | E19: ='DAXX MIDIA PE'!$S267 -> 0 | F19: ='DAXX MIDIA PE'!$S269 -> 1366.62
A20: ='DAXX MIDIA PE'!$T1 -> 46039 | C20: ='DAXX MIDIA PE'!$T255 -> 1366.62 | D20: ='DAXX MIDIA PE'!$T261 -> 0 | E20: ='DAXX MIDIA PE'!$T267 -> 0 | F20: ='DAXX MIDIA PE'!$T269 -> 1366.62
A21: ='DAXX MIDIA PE'!$U1 -> 46040 | C21: ='DAXX MIDIA PE'!$U255 -> 1366.62 | D21: ='DAXX MIDIA PE'!$U261 -> 0 | E21: ='DAXX MIDIA PE'!$U267 -> 0 | F21: ='DAXX MIDIA PE'!$U269 -> 1366.62
A22: ='DAXX MIDIA PE'!$V1 -> 46041 | C22: ='DAXX MIDIA PE'!$V255 -> 1366.62 | D22: ='DAXX MIDIA PE'!$V261 -> 0 | E22: ='DAXX MIDIA PE'!$V267 -> 0 | F22: ='DAXX MIDIA PE'!$V269 -> 1366.62
A23: ='DAXX MIDIA PE'!$W1 -> 46042 | C23: ='DAXX MIDIA PE'!$W255 -> 1352.65 | D23: ='DAXX MIDIA PE'!$W261 -> 0 | E23: ='DAXX MIDIA PE'!$W267 -> 0 | F23: ='DAXX MIDIA PE'!$W269 -> 1352.65
A24: ='DAXX MIDIA PE'!$X1 -> 46043 | C24: ='DAXX MIDIA PE'!$X255 -> 1352.65 | D24: ='DAXX MIDIA PE'!$X261 -> 0 | E24: ='DAXX MIDIA PE'!$X267 -> 0 | F24: ='DAXX MIDIA PE'!$X269 -> 1352.65
A25: ='DAXX MIDIA PE'!$Y1 -> 46044 | C25: ='DAXX MIDIA PE'!$Y255 -> 1352.65 | D25: ='DAXX MIDIA PE'!$Y261 -> 0 | E25: ='DAXX MIDIA PE'!$Y267 -> 0 | F25: ='DAXX MIDIA PE'!$Y269 -> 1352.65
A26: ='DAXX MIDIA PE'!$Z1 -> 46045 | C26: ='DAXX MIDIA PE'!$Z255 -> 1352.65 | D26: ='DAXX MIDIA PE'!$Z261 -> 0 | E26: ='DAXX MIDIA PE'!$Z267 -> 0 | F26: ='DAXX MIDIA PE'!$Z269 -> 1352.65
A27: ='DAXX MIDIA PE'!$AA1 -> 46046 | C27: ='DAXX MIDIA PE'!$AA255 -> 1352.65 | D27: ='DAXX MIDIA PE'!$AA261 -> 0 | E27: ='DAXX MIDIA PE'!$AA267 -> 0 | F27: ='DAXX MIDIA PE'!$AA269 -> 1352.65
A28: ='DAXX MIDIA PE'!$AB1 -> 46047 | C28: ='DAXX MIDIA PE'!$AB255 -> 1352.65 | D28: ='DAXX MIDIA PE'!$AB261 -> 0 | E28: ='DAXX MIDIA PE'!$AB267 -> 0 | F28: ='DAXX MIDIA PE'!$AB269 -> 1352.65
A29: ='DAXX MIDIA PE'!$AC1 -> 46048 | C29: ='DAXX MIDIA PE'!$AC255 -> 1123.26 | D29: ='DAXX MIDIA PE'!$AC261 -> 0 | E29: ='DAXX MIDIA PE'!$AC267 -> 0 | F29: ='DAXX MIDIA PE'!$AC269 -> 1123.26
A30: ='DAXX MIDIA PE'!$AD1 -> 46049 | C30: ='DAXX MIDIA PE'!$AD255 -> 1123.26 | D30: ='DAXX MIDIA PE'!$AD261 -> 0 | E30: ='DAXX MIDIA PE'!$AD267 -> 0 | F30: ='DAXX MIDIA PE'!$AD269 -> 1123.26
A31: ='DAXX MIDIA PE'!$AE1 -> 46050 | C31: ='DAXX MIDIA PE'!$AE255 -> 1123.26 | D31: ='DAXX MIDIA PE'!$AE261 -> 0 | E31: ='DAXX MIDIA PE'!$AE267 -> 0 | F31: ='DAXX MIDIA PE'!$AE269 -> 1123.26
A32: ='DAXX MIDIA PE'!$AF1 -> 46051 | C32: ='DAXX MIDIA PE'!$AF255 -> 1123.26 | D32: ='DAXX MIDIA PE'!$AF261 -> 0 | E32: ='DAXX MIDIA PE'!$AF267 -> 0 | F32: ='DAXX MIDIA PE'!$AF269 -> 1123.26
A33: ='DAXX MIDIA PE'!$AG1 -> 46052 | C33: ='DAXX MIDIA PE'!$AG255 -> 501.03 | D33: ='DAXX MIDIA PE'!$AG261 -> 0 | E33: ='DAXX MIDIA PE'!$AG267 -> 0 | F33: ='DAXX MIDIA PE'!$AG269 -> 501.03
A34: ='DAXX MIDIA PE'!$AH1 -> 46053 | C34: ='DAXX MIDIA PE'!$AH255 -> 501.03 | D34: ='DAXX MIDIA PE'!$AH261 -> 0 | E34: ='DAXX MIDIA PE'!$AH267 -> 0 | F34: ='DAXX MIDIA PE'!$AH269 -> 501.03
A35: ='DAXX MIDIA PE'!$AK1 -> 46054 | C35: ='DAXX MIDIA PE'!$AK255 -> 501.03 | D35: ='DAXX MIDIA PE'!$AK261 -> 0 | E35: ='DAXX MIDIA PE'!$AK267 -> 0 | F35: ='DAXX MIDIA PE'!$AK269 -> 501.03
A36: ='DAXX MIDIA PE'!$AL1 -> 46055 | C36: ='DAXX MIDIA PE'!$AL255 -> 501.03 | D36: ='DAXX MIDIA PE'!$AL261 -> 0 | E36: ='DAXX MIDIA PE'!$AL267 -> 0 | F36: ='DAXX MIDIA PE'!$AL269 -> 501.03
A37: ='DAXX MIDIA PE'!$AM1 -> 46056 | C37: ='DAXX MIDIA PE'!$AM255 -> 501.03 | D37: ='DAXX MIDIA PE'!$AM261 -> 0 | E37: ='DAXX MIDIA PE'!$AM267 -> 0 | F37: ='DAXX MIDIA PE'!$AM269 -> 501.03
A38: ='DAXX MIDIA PE'!$AN1 -> 46057 | C38: ='DAXX MIDIA PE'!$AN255 -> 501.03 | D38: ='DAXX MIDIA PE'!$AN261 -> 0 | E38: ='DAXX MIDIA PE'!$AN267 -> 0 | F38: ='DAXX MIDIA PE'!$AN269 -> 501.03
A39: ='DAXX MIDIA PE'!$AO1 -> 46058 | C39: ='DAXX MIDIA PE'!$AO255 -> 19690.53 | D39: ='DAXX MIDIA PE'!$AO261 -> 0 | E39: ='DAXX MIDIA PE'!$AO267 -> 0 | F39: ='DAXX MIDIA PE'!$AO269 -> 19690.53
A40: ='DAXX MIDIA PE'!$AP1 -> 46059 | C40: ='DAXX MIDIA PE'!$AP255 -> 19690.53 | D40: ='DAXX MIDIA PE'!$AP261 -> 0 | E40: ='DAXX MIDIA PE'!$AP267 -> 0 | F40: ='DAXX MIDIA PE'!$AP269 -> 19690.53
A41: ='DAXX MIDIA PE'!$AQ1 -> 46060 | C41: ='DAXX MIDIA PE'!$AQ255 -> 19690.53 | D41: ='DAXX MIDIA PE'!$AQ261 -> 0 | E41: ='DAXX MIDIA PE'!$AQ267 -> 0 | F41: ='DAXX MIDIA PE'!$AQ269 -> 19690.53
...
